Workbook

Sheet Annahmen
A1: Cirrus SF50 Vision Jet G3 – Startstrecken-, Zuladungs- und Reichweitenanalyse
A2: Quelle Flugzeugdaten: cirrusaircraft.com/aircraft/vision-jet (Stand 07/2026) · Flugplatzdaten: OurAirports (Open Data)
A4: FLUGZEUGDATEN (Herstellerangaben)
A5: Max. Startmasse (MTOW) | B5: 2727 | C5: kg
A6: Leermasse (BEW, Standardausstattung) | B6: 1610 | C6: kg
A7: Max. Masse ohne Kraftstoff (MZFW) | B7: 2223 | C7: kg
A8: Max. ausfliegbarer Kraftstoff | B8: 907 | C8: kg
A9: Max. Kraftstoff (Volumen) | B9: 296 | C9: US gal
A10: Startstrecke über 15 m Hindernis (MSL, ISA, MTOW) | B10: 858 | C10: m
A11: Startrollstrecke (MSL, ISA, MTOW) | B11: 582 | C11: m
A12: Landerollstrecke | B12: 494 | C12: m
A13: Max. Reisegeschwindigkeit | B13: 317 | C13: KTAS
A14: Max. Reichweite (Herstellerangabe) | B14: 1275 | C14: NM
A16: ANNAHMEN (blau = frei änderbar)
A17: Masse je Person (inkl. Handgepäck) | B17: 70 | C17: kg
A18: Gepäck je Person | B18: 20 | C18: kg
A19: Sicherheits-/Temperaturzuschlag (ISA+15, nass, Marge) | B19: 1.3 | C19: Faktor
A20: Höhenzuschlag je 1.000 ft Platzhöhe | B20: 0.09 | C20: Faktor
A22: REICHWEITEN-PARAMETER
A23: Kraftstoff Rollen/Start | B23: 10 | C23: gal
A24: Kraftstoff Steigflug auf FL310 | B24: 50 | C24: gal
A25: Im Steigflug zurückgelegte Strecke | B25: 90 | C25: NM
A26: Reserve Sparflug (45 min + Anflug) | B26: 40 | C26: gal
A27: Reserve Schnellflug (NBAA-nah) | B27: 55 | C27: gal
A28: Sparflug (LRC): Geschwindigkeit | B28: 240 | C28: KTAS
A29: Sparflug (LRC): Verbrauch | B29: 40 | C29: gal/h
A30: Schnellflug FL310: Geschwindigkeit | B30: 311 | C30: KTAS
A31: Schnellflug FL310: Verbrauch | B31: 65 | C31: gal/h
A33: VARIANTEN – sortiert nach Startmasse aufsteigend
A34: Variante | B34: Pers. | C34: Gepäck (kg) | D34: Kraftstoff (kg) | E34: Kraftstoff (gal) | F34: Tankfüllung | G34: Startmasse (kg) | H34: ZFW (kg) | I34: MTOW ok? | J34: MZFW ok? | K34: Erf. Bahn MSL (m) | L34: Reichweite Sparflug (km) | M34: Reichweite Schnellflug (km)
A35: V1: 2 Personen, Tank wie V4 (64 %) | B35: 2 | C35: =B35*$B$18 -> 40 | D35: =ROUND(D38,0) -> 577 | E35: =ROUND(D35*$B$9/$B$8,0) -> 188 | F35: =D35/$B$8 -> 0.63616318 | G35: =H35+D35 -> 2367 | H35: =$B$6+B35*$B$17+C35 -> 1790 | I35: =IF(G35<=$B$5,"ja","NEIN") -> ja | J35: =IF(H35<=$B$7,"ja","NEIN") -> ja | K35: =ROUND($B$10*(G35/$B$5)^2*$B$19,0) -> 840 | L35: =ROUND((MAX(0,E35-$B$23-$B$24-$B$26)/$B$29*$B$28+$B$25)*1.852,0) -> 1145 | M35: =ROUND((MAX(0,E35-$B$23-$B$24-$B$27)/$B$31*$B$30+$B$25)*1.852,0) -> 814
A36: V2: 2 Personen, maximal getankt | B36: 2 | C36: =B36*$B$18 -> 40 | D36: =ROUND(MIN($B$8,$B$5-H36),0) -> 907 | E36: =ROUND(D36*$B$9/$B$8,0) -> 296 | F36: =D36/$B$8 -> 1 | G36: =H36+D36 -> 2697 | H36: =$B$6+B36*$B$17+C36 -> 1790 | I36: =IF(G36<=$B$5,"ja","NEIN") -> ja | J36: =IF(H36<=$B$7,"ja","NEIN") -> ja | K36: =ROUND($B$10*(G36/$B$5)^2*$B$19,0) -> 1091 | L36: =ROUND((MAX(0,E36-$B$23-$B$24-$B$26)/$B$29*$B$28+$B$25)*1.852,0) -> 2345 | M36: =ROUND((MAX(0,E36-$B$23-$B$24-$B$27)/$B$31*$B$30+$B$25)*1.852,0) -> 1771
A37: V3: 4 Personen, maximal getankt | B37: 4 | C37: =B37*$B$18 -> 80 | D37: =ROUND(MIN($B$8,$B$5-H37),0) -> 757 | E37: =ROUND(D37*$B$9/$B$8,0) -> 247 | F37: =D37/$B$8 -> 0.83461963 | G37: =H37+D37 -> 2727 | H37: =$B$6+B37*$B$17+C37 -> 1970 | I37: =IF(G37<=$B$5,"ja","NEIN") -> ja | J37: =IF(H37<=$B$7,"ja","NEIN") -> ja | K37: =ROUND($B$10*(G37/$B$5)^2*$B$19,0) -> 1115 | L37: =ROUND((MAX(0,E37-$B$23-$B$24-$B$26)/$B$29*$B$28+$B$25)*1.852,0) -> 1800 | M37: =ROUND((MAX(0,E37-$B$23-$B$24-$B$27)/$B$31*$B$30+$B$25)*1.852,0) -> 1336
A38: V4: 6 Personen, maximal getankt | B38: 6 | C38: =B38*$B$18 -> 120 | D38: =ROUND(MIN($B$8,$B$5-H38),0) -> 577 | E38: =ROUND(D38*$B$9/$B$8,0) -> 188 | F38: =D38/$B$8 -> 0.63616318 | G38: =H38+D38 -> 2727 | H38: =$B$6+B38*$B$17+C38 -> 2150 | I38: =IF(G38<=$B$5,"ja","NEIN") -> ja | J38: =IF(H38<=$B$7,"ja","NEIN") -> ja | K38: =ROUND($B$10*(G38/$B$5)^2*$B$19,0) -> 1115 | L38: =ROUND((MAX(0,E38-$B$23-$B$24-$B$26)/$B$29*$B$28+$B$25)*1.852,0) -> 1145 | M38: =ROUND((MAX(0,E38-$B$23-$B$24-$B$27)/$B$31*$B$30+$B$25)*1.852,0) -> 814
A40: Hinweise:
A41: • Spalten sind nach Startmasse aufsteigend sortiert; V2–V4 zugleich nach Reichweite absteigend.
A42: V1 ist die Kurzbahn-Variante: gleiche Tankmenge wie V4, dadurch geringste Startmasse und kürzeste erforderliche Bahn.
A43: • Startstrecke skaliert näherungsweise mit (Startmasse/MTOW)^2.
A44: • Erf. Bahn = Startstrecke über 15 m Hindernis x (W/MTOW)^2 x Sicherheitsfaktor, im Flugplatzblatt zusätzlich x Höhenzuschlag.
A45: • Der Vision Jet benötigt eine befestigte Bahn (Asphalt/Beton); Grasplätze sind nicht zulässig.
...

Sheet Flugplätze Europa
A1: Flugplätze in Europa mit befestigter Bahn > 500 m – Eignung für den Cirrus Vision Jet G3
A2: "ja" = Bahnlänge reicht inkl. Sicherheits- und Höhenzuschlag · Bahnlänge = physische Piste, deklarierte Werte (TORA/LDA) laut AIP prüfen · Russland nicht enthalten · reine Militärplätze ausgeschlossen
A4: Flugplatz | B4: Kennung (ICAO) | C4: Bahnlänge (m) | D4: Platzhöhe (ft) | E4: Belag | F4: ="V1: 2 Pers. + 40 kg Gepäck, Tank 64 %"&CHAR(10)&"MTOM "&TEXT(Annahmen!$G$35,"0")&" kg · Tank "&TEXT(Annahmen!$D$35,"0")&" kg ("&TEXT(Annahmen!$F$35,"0%")&")"&CHAR(10)&"Reichweite "&TEXT(Annahmen!$L$35,"0")&" / "&TEXT(Annahmen!$M$35,"0")&" km" -> V1: 2 Pers. + 40 kg Gepäck, Tank 64 % MTOM 2367 kg · Tank 577 kg (64%) Reichweite 1145 / 814 km | G4: ="V2: 2 Pers. + 40 kg Gepäck, voller Tank"&CHAR(10)&"MTOM "&TEXT(Annahmen!$G$36,"0")&" kg · Tank "&TEXT(Annahmen!$D$36,"0")&" kg ("&TEXT(Annahmen!$F$36,"0%")&")"&CHAR(10)&"Reichweite "&TEXT(Annahmen!$L$36,"0")&" / "&TEXT(Annahmen!$M$36,"0")&" km" -> V2: 2 Pers. + 40 kg Gepäck, voller Tank MTOM 2697 kg · Tank 907 kg (100%) Reichweite 2345 / 1771 km | H4: ="V3: 4 Pers. + 80 kg Gepäck, max. Tank"&CHAR(10)&"MTOM "&TEXT(Annahmen!$G$37,"0")&" kg · Tank "&TEXT(Annahmen!$D$37,"0")&" kg ("&TEXT(Annahmen!$F$37,"0%")&")"&CHAR(10)&"Reichweite "&TEXT(Annahmen!$L$37,"0")&" / "&TEXT(Annahmen!$M$37,"0")&" km" -> V3: 4 Pers. + 80 kg Gepäck, max. Tank MTOM 2727 kg · Tank 757 kg (83%) Reichweite 1800 / 1336 km | I4: ="V4: 6 Pers. + 120 kg Gepäck, max. Tank"&CHAR(10)&"MTOM "&TEXT(Annahmen!$G$38,"0")&" kg · Tank "&TEXT(Annahmen!$D$38,"0")&" kg ("&TEXT(Annahmen!$F$38,"0%")&")"&CHAR(10)&"Reichweite "&TEXT(Annahmen!$L$38,"0")&" / "&TEXT(Annahmen!$M$38,"0")&" km" -> V4: 6 Pers. + 120 kg Gepäck, max. Tank MTOM 2727 kg · Tank 577 kg (64%) Reichweite 1145 / 814 km | J4: Erf. Bahn V1 (m) | K4: Erf. Bahn V2 (m) | L4: Erf. Bahn V3 (m) | M4: Erf. Bahn V4 (m) | N4: Kategorie / Bemerkung
A5: Albanien (2 Flugplätze)
A6: Tirana International Airport Mother Teresa | B6: LATI | C6: 3000 | D6: 126 | E6: Asphalt/Beton | F6: =IF(C6>=J6,"ja","nein") -> ja | G6: =IF(C6>=K6,"ja","nein") -> ja | H6: =IF(C6>=L6,"ja","nein") -> ja | I6: =IF(C6>=M6,"ja","nein") -> ja | J6: =ROUND(Annahmen!$K$35*(1+Annahmen!$B$20*D6/1000),0) -> 850 | K6: =ROUND(Annahmen!$K$36*(1+Annahmen!$B$20*D6/1000),0) -> 1103 | L6: =ROUND(Annahmen!$K$37*(1+Annahmen!$B$20*D6/1000),0) -> 1128 | M6: =ROUND(Annahmen!$K$38*(1+Annahmen!$B$20*D6/1000),0) -> 1128 | N6: Verkehrsflughafen
A7: Kukës International Airport | B7: LAKU | C7: 2198 | D7: 1120 | E7: Asphalt/Beton | F7: =IF(C7>=J7,"ja","nein") -> ja | G7: =IF(C7>=K7,"ja","nein") -> ja | H7: =IF(C7>=L7,"ja","nein") -> ja | I7: =IF(C7>=M7,"ja","nein") -> ja | J7: =ROUND(Annahmen!$K$35*(1+Annahmen!$B$20*D7/1000),0) -> 925 | K7: =ROUND(Annahmen!$K$36*(1+Annahmen!$B$20*D7/1000),0) -> 1201 | L7: =ROUND(Annahmen!$K$37*(1+Annahmen!$B$20*D7/1000),0) -> 1227 | M7: =ROUND(Annahmen!$K$38*(1+Annahmen!$B$20*D7/1000),0) -> 1227 | N7: Verkehrslandeplatz
A8: Belarus (7 Flugplätze)
A9: Minsk National Airport | B9: UMMS | C9: 3700 | D9: 670 | E9: Asphalt/Beton | F9: =IF(C9>=J9,"ja","nein") -> ja | G9: =IF(C9>=K9,"ja","nein") -> ja | H9: =IF(C9>=L9,"ja","nein") -> ja | I9: =IF(C9>=M9,"ja","nein") -> ja | J9: =ROUND(Annahmen!$K$35*(1+Annahmen!$B$20*D9/1000),0) -> 891 | K9: =ROUND(Annahmen!$K$36*(1+Annahmen!$B$20*D9/1000),0) -> 1157 | L9: =ROUND(Annahmen!$K$37*(1+Annahmen!$B$20*D9/1000),0) -> 1182 | M9: =ROUND(Annahmen!$K$38*(1+Annahmen!$B$20*D9/1000),0) -> 1182 | N9: Verkehrsflughafen
A10: Brest International Airport | B10: UMBB | C10: 2620 | D10: 468 | E10: Asphalt/Beton | F10: =IF(C10>=J10,"ja","nein") -> ja | G10: =IF(C10>=K10,"ja","nein") -> ja | H10: =IF(C10>=L10,"ja","nein") -> ja | I10: =IF(C10>=M10,"ja","nein") -> ja | J10: =ROUND(Annahmen!$K$35*(1+Annahmen!$B$20*D10/1000),0) -> 875 | K10: =ROUND(Annahmen!$K$36*(1+Annahmen!$B$20*D10/1000),0) -> 1137 | L10: =ROUND(Annahmen!$K$37*(1+Annahmen!$B$20*D10/1000),0) -> 1162 | M10: =ROUND(Annahmen!$K$38*(1+Annahmen!$B$20*D10/1000),0) -> 1162 | N10: Verkehrsflughafen
A11: Vitebsk Vostochny Airport | B11: UMII | C11: 2606 | D11: 682 | E11: Asphalt/Beton | F11: =IF(C11>=J11,"ja","nein") -> ja | G11: =IF(C11>=K11,"ja","nein") -> ja | H11: =IF(C11>=L11,"ja","nein") -> ja | I11: =IF(C11>=M11,"ja","nein") -> ja | J11: =ROUND(Annahmen!$K$35*(1+Annahmen!$B$20*D11/1000),0) -> 892 | K11: =ROUND(Annahmen!$K$36*(1+Annahmen!$B$20*D11/1000),0) -> 1158 | L11: =ROUND(Annahmen!$K$37*(1+Annahmen!$B$20*D11/1000),0) -> 1183 | M11: =ROUND(Annahmen!$K$38*(1+Annahmen!$B$20*D11/1000),0) -> 1183 | N11: Verkehrslandeplatz
A12: Gomel Airport | B12: UMGG | C12: 2569 | D12: 472 | E12: Asphalt/Beton | F12: =IF(C12>=J12,"ja","nein") -> ja | G12: =IF(C12>=K12,"ja","nein") -> ja | H12: =IF(C12>=L12,"ja","nein") -> ja | I12: =IF(C12>=M12,"ja","nein") -> ja | J12: =ROUND(Annahmen!$K$35*(1+Annahmen!$B$20*D12/1000),0) -> 876 | K12: =ROUND(Annahmen!$K$36*(1+Annahmen!$B$20*D12/1000),0) -> 1137 | L12: =ROUND(Annahmen!$K$37*(1+Annahmen!$B$20*D12/1000),0) -> 1162 | M12: =ROUND(Annahmen!$K$38*(1+Annahmen!$B$20*D12/1000),0) -> 1162 | N12: Verkehrslandeplatz
A13: Mogilev Airport | B13: UMOO | C13: 2567 | D13: 637 | E13: Asphalt/Beton | F13: =IF(C13>=J13,"ja","nein") -> ja | G13: =IF(C13>=K13,"ja","nein") -> ja | H13: =IF(C13>=L13,"ja","nein") -> ja | I13: =IF(C13>=M13,"ja","nein") -> ja | J13: =ROUND(Annahmen!$K$35*(1+Annahmen!$B$20*D13/1000),0) -> 888 | K13: =ROUND(Annahmen!$K$36*(1+Annahmen!$B$20*D13/1000),0) -> 1154 | L13: =ROUND(Annahmen!$K$37*(1+Annahmen!$B$20*D13/1000),0) -> 1179 | M13: =ROUND(Annahmen!$K$38*(1+Annahmen!$B$20*D13/1000),0) -> 1179 | N13: Verkehrslandeplatz
A14: Hrodna Airport | B14: UMMG | C14: 2560 | D14: 443 | E14: Asphalt/Beton | F14: =IF(C14>=J14,"ja","nein") -> ja | G14: =IF(C14>=K14,"ja","nein") -> ja | H14: =IF(C14>=L14,"ja","nein") -> ja | I14: =IF(C14>=M14,"ja","nein") -> ja | J14: =ROUND(Annahmen!$K$35*(1+Annahmen!$B$20*D14/1000),0) -> 873 | K14: =ROUND(Annahmen!$K$36*(1+Annahmen!$B$20*D14/1000),0) -> 1134 | L14: =ROUND(Annahmen!$K$37*(1+Annahmen!$B$20*D14/1000),0) -> 1159 | M14: =ROUND(Annahmen!$K$38*(1+Annahmen!$B$20*D14/1000),0) -> 1159 | N14: Verkehrslandeplatz
A15: Dzerzhinsky Highway Strip | B15: BY-0022 | C15: 2360 | D15: 690 | E15: Asphalt/Beton | F15: =IF(C15>=J15,"ja","nein") -> ja | G15: =IF(C15>=K15,"ja","nein") -> ja | H15: =IF(C15>=L15,"ja","nein") -> ja | I15: =IF(C15>=M15,"ja","nein") -> ja | J15: =ROUND(Annahmen!$K$35*(1+Annahmen!$B$20*D15/1000),0) -> 892 | K15: =ROUND(Annahmen!$K$36*(1+Annahmen!$B$20*D15/1000),0) -> 1159 | L15: =ROUND(Annahmen!$K$37*(1+Annahmen!$B$20*D15/1000),0) -> 1184 | M15: =ROUND(Annahmen!$K$38*(1+Annahmen!$B$20*D15/1000),0) -> 1184 | N15: Landeplatz
A16: Belgien (15 Flugplätze)
A17: Liège Airport | B17: EBLG | C17: 3690 | D17: 659 | E17: Asphalt/Beton | F17: =IF(C17>=J17,"ja","nein") -> ja | G17: =IF(C17>=K17,"ja","nein") -> ja | H17: =IF(C17>=L17,"ja","nein") -> ja | I17: =IF(C17>=M17,"ja","nein") -> ja | J17: =ROUND(Annahmen!$K$35*(1+Annahmen!$B$20*D17/1000),0) -> 890 | K17: =ROUND(Annahmen!$K$36*(1+Annahmen!$B$20*D17/1000),0) -> 1156 | L17: =ROUND(Annahmen!$K$37*(1+Annahmen!$B$20*D17/1000),0) -> 1181 | M17: =ROUND(Annahmen!$K$38*(1+Annahmen!$B$20*D17/1000),0) -> 1181 | N17: Verkehrslandeplatz
A18: Brussels Airport | B18: EBBR | C18: 3638 | D18: 175 | E18: Asphalt/Beton | F18: =IF(C18>=J18,"ja","nein") -> ja | G18: =IF(C18>=K18,"ja","nein") -> ja | H18: =IF(C18>=L18,"ja","nein") -> ja | I18: =IF(C18>=M18,"ja","nein") -> ja | J18: =ROUND(Annahmen!$K$35*(1+Annahmen!$B$20*D18/1000),0) -> 853 | K18: =ROUND(Annahmen!$K$36*(1+Annahmen!$B$20*D18/1000),0) -> 1108 | L18: =ROUND(Annahmen!$K$37*(1+Annahmen!$B$20*D18/1000),0) -> 1133 | M18: =ROUND(Annahmen!$K$38*(1+Annahmen!$B$20*D18/1000),0) -> 1133 | N18: Verkehrsflughafen
A19: Ostend-Bruges International Airport | B19: EBOS | C19: 3200 | D19: 13 | E19: Asphalt/Beton | F19: =IF(C19>=J19,"ja","nein") -> ja | G19: =IF(C19>=K19,"ja","nein") -> ja | H19: =IF(C19>=L19,"ja","nein") -> ja | I19: =IF(C19>=M19,"ja","nein") -> ja | J19: =ROUND(Annahmen!$K$35*(1+Annahmen!$B$20*D19/1000),0) -> 841 | K19: =ROUND(Annahmen!$K$36*(1+Annahmen!$B$20*D19/1000),0) -> 1092 | L19: =ROUND(Annahmen!$K$37*(1+Annahmen!$B$20*D19/1000),0) -> 1116 | M19: =ROUND(Annahmen!$K$38*(1+Annahmen!$B$20*D19/1000),0) -> 1116 | N19: Verkehrsflughafen
A20: Brussels South Charleroi Airport | B20: EBCI | C20: 3055 | D20: 614 | E20: Asphalt/Beton | F20: =IF(C20>=J20,"ja","nein") -> ja | G20: =IF(C20>=K20,"ja","nein") -> ja | H20: =IF(C20>=L20,"ja","nein") -> ja | I20: =IF(C20>=M20,"ja","nein") -> ja | J20: =ROUND(Annahmen!$K$35*(1+Annahmen!$B$20*D20/1000),0) -> 886 | K20: =ROUND(Annahmen!$K$36*(1+Annahmen!$B$20*D20/1000),0) -> 1151 | L20: =ROUND(Annahmen!$K$37*(1+Annahmen!$B$20*D20/1000),0) -> 1177 | M20: =ROUND(Annahmen!$K$38*(1+Annahmen!$B$20*D20/1000),0) -> 1177 | N20: Verkehrsflughafen
A21: Kortrijk-Wevelgem International Airport | B21: EBKT | C21: 1900 | D21: 55 | E21: Asphalt/Beton | F21: =IF(C21>=J21,"ja","nein") -> ja | G21: =IF(C21>=K21,"ja","nein") -> ja | H21: =IF(C21>=L21,"ja","nein") -> ja | I21: =IF(C21>=M21,"ja","nein") -> ja | J21: =ROUND(Annahmen!$K$35*(1+Annahmen!$B$20*D21/1000),0) -> 844 | K21: =ROUND(Annahmen!$K$36*(1+Annahmen!$B$20*D21/1000),0) -> 1096 | L21: =ROUND(Annahmen!$K$37*(1+Annahmen!$B$20*D21/1000),0) -> 1121 | M21: =ROUND(Annahmen!$K$38*(1+Annahmen!$B$20*D21/1000),0) -> 1121 | N21: Verkehrslandeplatz
A22: Antwerp International Airport (Deurne) | B22: EBAW | C22: 1510 | D22: 39 | E22: Asphalt/Beton | F22: =IF(C22>=J22,"ja","nein") -> ja | G22: =IF(C22>=K22,"ja","nein") -> ja | H22: =IF(C22>=L22,"ja","nein") -> ja | I22: =IF(C22>=M22,"ja","nein") -> ja | J22: =ROUND(Annahmen!$K$35*(1+Annahmen!$B$20*D22/1000),0) -> 843 | K22: =ROUND(Annahmen!$K$36*(1+Annahmen!$B$20*D22/1000),0) -> 1095 | L22: =ROUND(Annahmen!$K$37*(1+Annahmen!$B$20*D22/1000),0) -> 1119 | M22: =ROUND(Annahmen!$K$38*(1+Annahmen!$B$20*D22/1000),0) -> 1119 | N22: Verkehrslandeplatz
A23: Sint-Truiden / Brustem Airfield | B23: EBST | C23: 1096 | D23: 246 | E23: Asphalt/Beton | F23: =IF(C23>=J23,"ja","nein") -> ja | G23: =IF(C23>=K23,"ja","nein") -> nein | H23: =IF(C23>=L23,"ja","nein") -> nein | I23: =IF(C23>=M23,"ja","nein") -> nein | J23: =ROUND(Annahmen!$K$35*(1+Annahmen!$B$20*D23/1000),0) -> 859 | K23: =ROUND(Annahmen!$K$36*(1+Annahmen!$B$20*D23/1000),0) -> 1115 | L23: =ROUND(Annahmen!$K$37*(1+Annahmen!$B$20*D23/1000),0) -> 1140 | M23: =ROUND(Annahmen!$K$38*(1+Annahmen!$B$20*D23/1000),0) -> 1140 | N23: Landeplatz
A24: Brasschaat Airfield | B24: EBBT | C24: 799 | D24: 76 | E24: Asphalt/Beton | F24: =IF(C24>=J24,"ja","nein") -> nein | G24: =IF(C24>=K24,"ja","nein") -> nein | H24: =IF(C24>=L24,"ja","nein") -> nein | I24: =IF(C24>=M24,"ja","nein") -> nein | J24: =ROUND(Annahmen!$K$35*(1+Annahmen!$B$20*D24/1000),0) -> 846 | K24: =ROUND(Annahmen!$K$36*(1+Annahmen!$B$20*D24/1000),0) -> 1098 | L24: =ROUND(Annahmen!$K$37*(1+Annahmen!$B$20*D24/1000),0) -> 1123 | M24: =ROUND(Annahmen!$K$38*(1+Annahmen!$B$20*D24/1000),0) -> 1123 | N24: Landeplatz
A25: Spa-La Sauvenière Airfield | B25: EBSP | C25: 799 | D25: 1581 | E25: Asphalt/Beton | F25: =IF(C25>=J25,"ja","nein") -> nein | G25: =IF(C25>=K25,"ja","nein") -> nein | H25: =IF(C25>=L25,"ja","nein") -> nein | I25: =IF(C25>=M25,"ja","nein") -> nein | J25: =ROUND(Annahmen!$K$35*(1+Annahmen!$B$20*D25/1000),0) -> 960 | K25: =ROUND(Annahmen!$K$36*(1+Annahmen!$B$20*D25/1000),0) -> 1246 | L25: =ROUND(Annahmen!$K$37*(1+Annahmen!$B$20*D25/1000),0) -> 1274 | M25: =ROUND(Annahmen!$K$38*(1+Annahmen!$B$20*D25/1000),0) -> 1274 | N25: Landeplatz
A26: Oostmalle Airfield | B26: EBZR | C26: 799 | D26: 53 | E26: Asphalt/Beton | F26: =IF(C26>=J26,"ja","nein") -> nein | G26: =IF(C26>=K26,"ja","nein") -> nein | H26: =IF(C26>=L26,"ja","nein") -> nein | I26: =IF(C26>=M26,"ja","nein") -> nein | J26: =ROUND(Annahmen!$K$35*(1+Annahmen!$B$20*D26/1000),0) -> 844 | K26: =ROUND(Annahmen!$K$36*(1+Annahmen!$B$20*D26/1000),0) -> 1096 | L26: =ROUND(Annahmen!$K$37*(1+Annahmen!$B$20*D26/1000),0) -> 1120 | M26: =ROUND(Annahmen!$K$38*(1+Annahmen!$B$20*D26/1000),0) -> 1120 | N26: Landeplatz
A27: Genk Zwartberg Airfield | B27: EBZW | C27: 799 | D27: 278 | E27: Asphalt/Beton | F27: =IF(C27>=J27,"ja","nein") -> nein | G27: =IF(C27>=K27,"ja","nein") -> nein | H27: =IF(C27>=L27,"ja","nein") -> nein | I27: =IF(C27>=M27,"ja","nein") -> nein | J27: =ROUND(Annahmen!$K$35*(1+Annahmen!$B$20*D27/1000),0) -> 861 | K27: =ROUND(Annahmen!$K$36*(1+Annahmen!$B$20*D27/1000),0) -> 1118 | L27: =ROUND(Annahmen!$K$37*(1+Annahmen!$B$20*D27/1000),0) -> 1143 | M27: =ROUND(Annahmen!$K$38*(1+Annahmen!$B$20*D27/1000),0) -> 1143 | N27: Landeplatz
A28: Goetsenhoven Airfield | B28: EBTN | C28: 780 | D28: 246 | E28: Asphalt/Beton | F28: =IF(C28>=J28,"ja","nein") -> nein | G28: =IF(C28>=K28,"ja","nein") -> nein | H28: =IF(C28>=L28,"ja","nein") -> nein | I28: =IF(C28>=M28,"ja","nein") -> nein | J28: =ROUND(Annahmen!$K$35*(1+Annahmen!$B$20*D28/1000),0) -> 859 | K28: =ROUND(Annahmen!$K$36*(1+Annahmen!$B$20*D28/1000),0) -> 1115 | L28: =ROUND(Annahmen!$K$37*(1+Annahmen!$B$20*D28/1000),0) -> 1140 | M28: =ROUND(Annahmen!$K$38*(1+Annahmen!$B$20*D28/1000),0) -> 1140 | N28: Landeplatz
... A31: Leopoldsburg Airfield | B31: EBLE | C31: 600 | D31: 207 | E31: Asphalt/Beton | F31: =IF(C31>=J31,"ja","nein") -> nein | G31: =IF(C31>=K31,"ja","nein") -> nein | H31: =IF(C31>=L31,"ja","nein") -> nein | I31: =IF(C31>=M31,"ja","nein") -> nein | J31: =ROUND(Annahmen!$K$35*(1+Annahmen!$B$20*D31/1000),0) -> 856 | K31: =ROUND(Annahmen!$K$36*(1+Annahmen!$B$20*D31/1000),0) -> 1111 | L31: =ROUND(Annahmen!$K$37*(1+Annahmen!$B$20*D31/1000),0) -> 1136 | M31: =ROUND(Annahmen!$K$38*(1+Annahmen!$B$20*D31/1000),0) -> 1136 | N31: Landeplatz
A32: Bosnien und Herzegowina (5 Flugplätze)
A33: Sarajevo International Airport | B33: LQSA | C33: 2641 | D33: 1708 | E33: Asphalt/Beton | F33: =IF(C33>=J33,"ja","nein") -> ja | G33: =IF(C33>=K33,"ja","nein") -> ja | H33: =IF(C33>=L33,"ja","nein") -> ja | I33: =IF(C33>=M33,"ja","nein") -> ja | J33: =ROUND(Annahmen!$K$35*(1+Annahmen!$B$20*D33/1000),0) -> 969 | K33: =ROUND(Annahmen!$K$36*(1+Annahmen!$B$20*D33/1000),0) -> 1259 | L33: =ROUND(Annahmen!$K$37*(1+Annahmen!$B$20*D33/1000),0) -> 1286 | M33: =ROUND(Annahmen!$K$38*(1+Annahmen!$B$20*D33/1000),0) -> 1286 | N33: Verkehrsflughafen
A34: Banja Luka International Airport | B34: LQBK | C34: 2500 | D34: 400 | E34: Asphalt/Beton | F34: =IF(C34>=J34,"ja","nein") -> ja | G34: =IF(C34>=K34,"ja","nein") -> ja | H34: =IF(C34>=L34,"ja","nein") -> ja | I34: =IF(C34>=M34,"ja","nein") -> ja | J34: =ROUND(Annahmen!$K$35*(1+Annahmen!$B$20*D34/1000),0) -> 870 | K34: =ROUND(Annahmen!$K$36*(1+Annahmen!$B$20*D34/1000),0) -> 1130 | L34: =ROUND(Annahmen!$K$37*(1+Annahmen!$B$20*D34/1000),0) -> 1155 | M34: =ROUND(Annahmen!$K$38*(1+Annahmen!$B$20*D34/1000),0) -> 1155 | N34: Verkehrsflughafen
A35: Tuzla International Airport | B35: LQTZ | C35: 2485 | D35: 784 | E35: Asphalt/Beton | F35: =IF(C35>=J35,"ja","nein") -> ja | G35: =IF(C35>=K35,"ja","nein") -> ja | H35: =IF(C35>=L35,"ja","nein") -> ja | I35: =IF(C35>=M35,"ja","nein") -> ja | J35: =ROUND(Annahmen!$K$35*(1+Annahmen!$B$20*D35/1000),0) -> 899 | K35: =ROUND(Annahmen!$K$36*(1+Annahmen!$B$20*D35/1000),0) -> 1168 | L35: =ROUND(Annahmen!$K$37*(1+Annahmen!$B$20*D35/1000),0) -> 1194 | M35: =ROUND(Annahmen!$K$38*(1+Annahmen!$B$20*D35/1000),0) -> 1194 | N35: Verkehrsflughafen
A36: Mostar International Airport | B36: LQMO | C36: 2400 | D36: 156 | E36: Asphalt/Beton | F36: =IF(C36>=J36,"ja","nein") -> ja | G36: =IF(C36>=K36,"ja","nein") -> ja | H36: =IF(C36>=L36,"ja","nein") -> ja | I36: =IF(C36>=M36,"ja","nein") -> ja | J36: =ROUND(Annahmen!$K$35*(1+Annahmen!$B$20*D36/1000),0) -> 852 | K36: =ROUND(Annahmen!$K$36*(1+Annahmen!$B$20*D36/1000),0) -> 1106 | L36: =ROUND(Annahmen!$K$37*(1+Annahmen!$B$20*D36/1000),0) -> 1131 | M36: =ROUND(Annahmen!$K$38*(1+Annahmen!$B$20*D36/1000),0) -> 1131 | N36: Verkehrsflughafen
A37: Brčko-Brod Airfield | B37: BA-0003 | C37: 582 | D37: 337 | E37: Asphalt/Beton | F37: =IF(C37>=J37,"ja","nein") -> nein | G37: =IF(C37>=K37,"ja","nein") -> nein | H37: =IF(C37>=L37,"ja","nein") -> nein | I37: =IF(C37>=M37,"ja","nein") -> nein | J37: =ROUND(Annahmen!$K$35*(1+Annahmen!$B$20*D37/1000),0) -> 865 | K37: =ROUND(Annahmen!$K$36*(1+Annahmen!$B$20*D37/1000),0) -> 1124 | L37: =ROUND(Annahmen!$K$37*(1+Annahmen!$B$20*D37/1000),0) -> 1149 | M37: =ROUND(Annahmen!$K$38*(1+Annahmen!$B$20*D37/1000),0) -> 1149 | N37: Landeplatz
A38: Bulgarien (14 Flugplätze)
A39: Sofia Airport | B39: LBSF | C39: 3600 | D39: 1742 | E39: Asphalt/Beton | F39: =IF(C39>=J39,"ja","nein") -> ja | G39: =IF(C39>=K39,"ja","nein") -> ja | H39: =IF(C39>=L39,"ja","nein") -> ja | I39: =IF(C39>=M39,"ja","nein") -> ja | J39: =ROUND(Annahmen!$K$35*(1+Annahmen!$B$20*D39/1000),0) -> 972 | K39: =ROUND(Annahmen!$K$36*(1+Annahmen!$B$20*D39/1000),0) -> 1262 | L39: =ROUND(Annahmen!$K$37*(1+Annahmen!$B$20*D39/1000),0) -> 1290 | M39: =ROUND(Annahmen!$K$38*(1+Annahmen!$B$20*D39/1000),0) -> 1290 | N39: Verkehrsflughafen
A40: Burgas Airport | B40: LBBG | C40: 3200 | D40: 135 | E40: Asphalt/Beton | F40: =IF(C40>=J40,"ja","nein") -> ja | G40: =IF(C40>=K40,"ja","nein") -> ja | H40: =IF(C40>=L40,"ja","nein") -> ja | I40: =IF(C40>=M40,"ja","nein") -> ja | J40: =ROUND(Annahmen!$K$35*(1+Annahmen!$B$20*D40/1000),0) -> 850 | K40: =ROUND(Annahmen!$K$36*(1+Annahmen!$B$20*D40/1000),0) -> 1104 | L40: =ROUND(Annahmen!$K$37*(1+Annahmen!$B$20*D40/1000),0) -> 1129 | M40: =ROUND(Annahmen!$K$38*(1+Annahmen!$B$20*D40/1000),0) -> 1129 | N40: Verkehrsflughafen
A41: Sapareva Banya Airport | B41: BG-0170 | C41: 2554 | D41: 2218 | E41: Asphalt/Beton | F41: =IF(C41>=J41,"ja","nein") -> ja | G41: =IF(C41>=K41,"ja","nein") -> ja | H41: =IF(C41>=L41,"ja","nein") -> ja | I41: =IF(C41>=M41,"ja","nein") -> ja | J41: =ROUND(Annahmen!$K$35*(1+Annahmen!$B$20*D41/1000),0) -> 1008 | K41: =ROUND(Annahmen!$K$36*(1+Annahmen!$B$20*D41/1000),0) -> 1309 | L41: =ROUND(Annahmen!$K$37*(1+Annahmen!$B$20*D41/1000),0) -> 1338 | M41: =ROUND(Annahmen!$K$38*(1+Annahmen!$B$20*D41/1000),0) -> 1338 | N41: Landeplatz
A42: Varna Airport | B42: LBWN | C42: 2517 | D42: 230 | E42: Asphalt/Beton | F42: =IF(C42>=J42,"ja","nein") -> ja | G42: =IF(C42>=K42,"ja","nein") -> ja | H42: =IF(C42>=L42,"ja","nein") -> ja | I42: =IF(C42>=M42,"ja","nein") -> ja | J42: =ROUND(Annahmen!$K$35*(1+Annahmen!$B$20*D42/1000),0) -> 857 | K42: =ROUND(Annahmen!$K$36*(1+Annahmen!$B$20*D42/1000),0) -> 1114 | L42: =ROUND(Annahmen!$K$37*(1+Annahmen!$B$20*D42/1000),0) -> 1138 | M42: =ROUND(Annahmen!$K$38*(1+Annahmen!$B$20*D42/1000),0) -> 1138 | N42: Verkehrsflughafen
A43: Ruse Airport | B43: LBRS | C43: 2502 | D43: 614 | E43: Asphalt/Beton | F43: =IF(C43>=J43,"ja","nein") -> ja | G43: =IF(C43>=K43,"ja","nein") -> ja | H43: =IF(C43>=L43,"ja","nein") -> ja | I43: =IF(C43>=M43,"ja","nein") -> ja | J43: =ROUND(Annahmen!$K$35*(1+Annahmen!$B$20*D43/1000),0) -> 886 | K43: =ROUND(Annahmen!$K$36*(1+Annahmen!$B$20*D43/1000),0) -> 1151 | L43: =ROUND(Annahmen!$K$37*(1+Annahmen!$B$20*D43/1000),0) -> 1177 | M43: =ROUND(Annahmen!$K$38*(1+Annahmen!$B$20*D43/1000),0) -> 1177 | N43: Landeplatz
...
